Workbook
Name ScenarioList: 'Assumptions_and_Inputs'!$B$5:$E$5

Sheet TOC_and_Summary
A1: Amok Equipment AS | Integrated 3-Statement Model
A2: =IF(Model_Checks!$B$2=0,"ALL CHECKS PASSED","MODEL CHECKS FAILED")
A3: Amok Equipment AS | NOK unless stated | Generated 2026-10-10 | Version 1.0
A4: Active scenario | B4: =Assumptions_and_Inputs!$B$4 | D4: Forecast period | E4: 2026-2030 | G4: Model status | H4: =Model_Checks!$A$2
A6: Selected-scenario financial overview (NOK)
A7: Metric | B7: 2023 | C7: 2024 | D7: 2025 | E7: 2026 | F7: 2027 | G7: 2028 | H7: 2029 | I7: 2030
A8: Revenue | B8: =Financial_Statements!B6 | C8: =Financial_Statements!C6 | D8: =Financial_Statements!D6 | E8: =Financial_Statements!E6 | F8: =Financial_Statements!F6 | G8: =Financial_Statements!G6 | H8: =Financial_Statements!H6 | I8: =Financial_Statements!I6
A9: EBITDA | B9: =Financial_Statements!B12 | C9: =Financial_Statements!C12 | D9: =Financial_Statements!D12 | E9: =Financial_Statements!E12 | F9: =Financial_Statements!F12 | G9: =Financial_Statements!G12 | H9: =Financial_Statements!H12 | I9: =Financial_Statements!I12
A10: EBITDA margin | B10: =Financial_Statements!B13 | C10: =Financial_Statements!C13 | D10: =Financial_Statements!D13 | E10: =Financial_Statements!E13 | F10: =Financial_Statements!F13 | G10: =Financial_Statements!G13 | H10: =Financial_Statements!H13 | I10: =Financial_Statements!I13
A11: Net income | B11: =Financial_Statements!B20 | C11: =Financial_Statements!C20 | D11: =Financial_Statements!D20 | E11: =Financial_Statements!E20 | F11: =Financial_Statements!F20 | G11: =Financial_Statements!G20 | H11: =Financial_Statements!H20 | I11: =Financial_Statements!I20
A12: Ending cash | B12: =Financial_Statements!B55 | C12: =Financial_Statements!C55 | D12: =Financial_Statements!D55 | E12: =Financial_Statements!E55 | F12: =Financial_Statements!F55 | G12: =Financial_Statements!G55 | H12: =Financial_Statements!H55 | I12: =Financial_Statements!I55
A13: Total debt | B13: =Financial_Statements!B31 | C13: =Financial_Statements!C31 | D13: =Financial_Statements!D31 | E13: =Financial_Statements!E31 | F13: =Financial_Statements!F31 | G13: =Financial_Statements!G31 | H13: =Financial_Statements!H31 | I13: =Financial_Statements!I31
A16: Scenario comparison | 2030 outcomes
A17: Scenario | B17: Revenue | C17: EBITDA | D17: EBITDA margin | E17: Ending cash | F17: Revolver debt | G17: Liquidity
A18: Base Case | B18: =Scenario_Analysis!B5 | C18: =Scenario_Analysis!B6 | D18: =Scenario_Analysis!B7 | E18: =Scenario_Analysis!B8 | F18: =Scenario_Analysis!B9 | G18: =Scenario_Analysis!B10
A19: Bull Case | B19: =Scenario_Analysis!C5 | C19: =Scenario_Analysis!C6 | D19: =Scenario_Analysis!C7 | E19: =Scenario_Analysis!C8 | F19: =Scenario_Analysis!C9 | G19: =Scenario_Analysis!C10
A20: Bear Case | B20: =Scenario_Analysis!D5 | C20: =Scenario_Analysis!D6 | D20: =Scenario_Analysis!D7 | E20: =Scenario_Analysis!D8 | F20: =Scenario_Analysis!D9 | G20: =Scenario_Analysis!D10
A21: Severe Stress | B21: =Scenario_Analysis!E5 | C21: =Scenario_Analysis!E6 | D21: =Scenario_Analysis!E7 | E21: =Scenario_Analysis!E8 | F21: =Scenario_Analysis!E9 | G21: =Scenario_Analysis!E10
A24: Workbook navigation
A25: Assumptions_and_Inputs | B25: Edit scenario selector and forecast assumptions
A26: Financial_Statements | B26: Integrated income statement, balance sheet, and cash flow
A27: Supporting_Schedules | B27: Working capital, PP&E, debt, and equity corkscrews
A28: Scenario_Analysis | B28: Compare scenario revenue and EBITDA
A29: Sensitivity_Analysis | B29: Two-way heatmap, tornado shocks, and elasticity
A30: Model_Checks | B30: Accounting and formula-integrity checks
A31: Historical_Data | B31: Source inputs and mapping notes
A34: Blue fill / blue font = editable input; green font = formula. Base-case forecast assumptions are illustrative and require management review.

Sheet Assumptions_and_Inputs
A1: Assumptions_and_Inputs | Centralized scenario drivers
A2: =IF(Model_Checks!$B$2=0,"ALL CHECKS PASSED","MODEL CHECKS FAILED")
A3: Amok Equipment AS | NOK unless stated | Generated 2026-10-10 | Version 1.0
A4: Active scenario | B4: Base Case
A5: Driver (forecast assumption) | B5: Base Case | C5: Bull Case | D5: Bear Case | E5: Severe Stress | F5: Active assumption
A6: Annual volume growth | B6: 0.02 | C6: 0.1 | D6: -0.04 | E6: -0.15 | F6: =IFERROR(INDEX($B6:$E6,1,MATCH($B$4,$B$5:$E$5,0)),0)
A7: Annual price realization growth | B7: 0.02 | C7: 0.03 | D7: 0.01 | E7: -0.02 | F7: =IFERROR(INDEX($B7:$E7,1,MATCH($B$4,$B$5:$E$5,0)),0)
A8: Non-personnel operating costs / revenue | B8: 0.7 | C8: 0.68 | D8: 0.83 | E8: 0.9 | F8: =IFERROR(INDEX($B8:$E8,1,MATCH($B$4,$B$5:$E$5,0)),0)
A9: Annual wage inflation | B9: 0.035 | C9: 0.03 | D9: 0.06 | E9: 0.08 | F9: =IFERROR(INDEX($B9:$E9,1,MATCH($B$4,$B$5:$E$5,0)),0)
A10: Accounts receivable days (DSO) | B10: 43 | C10: 38 | D10: 50 | E10: 60 | F10: =IFERROR(INDEX($B10:$E10,1,MATCH($B$4,$B$5:$E$5,0)),0)
A11: Inventory / other operating assets days (DIO) | B11: 325 | C11: 300 | D11: 360 | E11: 400 | F11: =IFERROR(INDEX($B11:$E11,1,MATCH($B$4,$B$5:$E$5,0)),0)
A12: Accounts payable days (DPO) | B12: 65 | C12: 70 | D12: 60 | E12: 50 | F12: =IFERROR(INDEX($B12:$E12,1,MATCH($B$4,$B$5:$E$5,0)),0)
A13: Capital expenditure / revenue | B13: 0.02 | C13: 0.025 | D13: 0.015 | E13: 0.01 | F13: =IFERROR(INDEX($B13:$E13,1,MATCH($B$4,$B$5:$E$5,0)),0)
A14: Depreciation rate on opening net PP&E + half-year CapEx | B14: 0.15 | C14: 0.15 | D14: 0.18 | E14: 0.2 | F14: =IFERROR(INDEX($B14:$E14,1,MATCH($B$4,$B$5:$E$5,0)),0)
A15: Cash interest yield | B15: 0.025 | C15: 0.03 | D15: 0.02 | E15: 0.015 | F15: =IFERROR(INDEX($B15:$E15,1,MATCH($B$4,$B$5:$E$5,0)),0)
A16: Revolver interest rate | B16: 0.07 | C16: 0.07 | D16: 0.09 | E16: 0.12 | F16: =IFERROR(INDEX($B16:$E16,1,MATCH($B$4,$B$5:$E$5,0)),0)
A17: Cash tax rate (no loss-carryforward benefit) | B17: 0.22 | C17: 0.22 | D17: 0.22 | E17: 0.22 | F17: =IFERROR(INDEX($B17:$E17,1,MATCH($B$4,$B$5:$E$5,0)),0)
... A22: Illustrative scenario probability | B22: 0.55 | C22: 0.2 | D22: 0.2 | E22: 0.05 | F22: =IFERROR(INDEX($B22:$E22,1,MATCH($B$4,$B$5:$E$5,0)),0)
A24: Days per year (working capital) | B24: 365
A25: Model check tolerance (NOK) | B25: 1.01
A26: Forecast years | B26: =COUNT(Financial_Statements!$E$4:$I$4)
A27: Model convention | B27: Annual forecast; interest uses opening cash/debt to prevent circularity. No unmanaged circular references.
A28: Actual / source convention | B28: Blue cells are hardcoded inputs; green-font cells are formulas. Forecast drivers are scenarios, not company guidance.

Sheet Financial_Statements
A1: Financial_Statements | Integrated income statement, balance sheet, and cash flow
A2: =IF(Model_Checks!$B$2=0,"ALL CHECKS PASSED","MODEL CHECKS FAILED")
A3: Amok Equipment AS | NOK unless stated | Generated 2026-10-10 | Version 1.0
A4: Fiscal year | B4: 2023 | C4: 2024 | D4: 2025 | E4: 2026 | F4: 2027 | G4: 2028 | H4: 2029 | I4: 2030
A5: Income statement (NOK, except percentages)
A6: Revenue | B6: =Historical_Data!$B$5 | C6: =Historical_Data!$C$5 | D6: =Historical_Data!$D$5 | E6: =D6*(1+Assumptions_and_Inputs!$F$6)*(1+Assumptions_and_Inputs!$F$7) | F6: =E6*(1+Assumptions_and_Inputs!$F$6)*(1+Assumptions_and_Inputs!$F$7) | G6: =F6*(1+Assumptions_and_Inputs!$F$6)*(1+Assumptions_and_Inputs!$F$7) | H6: =G6*(1+Assumptions_and_Inputs!$F$6)*(1+Assumptions_and_Inputs!$F$7) | I6: =H6*(1+Assumptions_and_Inputs!$F$6)*(1+Assumptions_and_Inputs!$F$7)
A7: Revenue growth | B7: ="" | C7: =IFERROR(C6/B6-1,0) | D7: =IFERROR(D6/C6-1,0) | E7: =IFERROR(E6/D6-1,0) | F7: =IFERROR(F6/E6-1,0) | G7: =IFERROR(G6/F6-1,0) | H7: =IFERROR(H6/G6-1,0) | I7: =IFERROR(I6/H6-1,0)
A8: Non-personnel operating expenses (proxy) | B8: =Historical_Data!$B$6-Historical_Data!$B$7 | C8: =Historical_Data!$C$6-Historical_Data!$C$7 | D8: =Historical_Data!$D$6-Historical_Data!$D$7 | E8: =E6*Assumptions_and_Inputs!$F$8 | F8: =F6*Assumptions_and_Inputs!$F$8 | G8: =G6*Assumptions_and_Inputs!$F$8 | H8: =H6*Assumptions_and_Inputs!$F$8 | I8: =I6*Assumptions_and_Inputs!$F$8
A9: Pre-personnel operating contribution | B9: =B6-B8 | C9: =C6-C8 | D9: =D6-D8 | E9: =E6-E8 | F9: =F6-F8 | G9: =G6-G8 | H9: =H6-H8 | I9: =I6-I8
A10: Pre-personnel contribution margin | B10: =IFERROR(B9/B6,0) | C10: =IFERROR(C9/C6,0) | D10: =IFERROR(D9/D6,0) | E10: =IFERROR(E9/E6,0) | F10: =IFERROR(F9/F6,0) | G10: =IFERROR(G9/G6,0) | H10: =IFERROR(H9/H6,0) | I10: =IFERROR(I9/I6,0)
A11: Personnel expenses | B11: =Historical_Data!$B$7 | C11: =Historical_Data!$C$7 | D11: =Historical_Data!$D$7 | E11: =D11*(1+Assumptions_and_Inputs!$F$6)*(1+Assumptions_and_Inputs!$F$9) | F11: =E11*(1+Assumptions_and_Inputs!$F$6)*(1+Assumptions_and_Inputs!$F$9) | G11: =F11*(1+Assumptions_and_Inputs!$F$6)*(1+Assumptions_and_Inputs!$F$9) | H11: =G11*(1+Assumptions_and_Inputs!$F$6)*(1+Assumptions_and_Inputs!$F$9) | I11: =H11*(1+Assumptions_and_Inputs!$F$6)*(1+Assumptions_and_Inputs!$F$9)
A12: EBITDA | B12: =B15+B14 | C12: =C15+C14 | D12: =D15+D14 | E12: =E9-E11 | F12: =F9-F11 | G12: =G9-G11 | H12: =H9-H11 | I12: =I9-I11
A13: EBITDA margin | B13: =IFERROR(B12/B6,0) | C13: =IFERROR(C12/C6,0) | D13: =IFERROR(D12/D6,0) | E13: =IFERROR(E12/E6,0) | F13: =IFERROR(F12/F6,0) | G13: =IFERROR(G12/G6,0) | H13: =IFERROR(H12/H6,0) | I13: =IFERROR(I12/I6,0)
A14: Depreciation and amortization | B14: =Historical_Data!B26 | C14: =Historical_Data!C26 | D14: =Historical_Data!D26 | E14: =Supporting_Schedules!E17 | F14: =Supporting_Schedules!F17 | G14: =Supporting_Schedules!G17 | H14: =Supporting_Schedules!H17 | I14: =Supporting_Schedules!I17
A15: Operating profit (EBIT) | B15: =Historical_Data!$B$8 | C15: =Historical_Data!$C$8 | D15: =Historical_Data!$D$8 | E15: =E12-E14 | F15: =F12-F14 | G15: =G12-G14 | H15: =H12-H14 | I15: =I12-I14
A16: EBIT margin | B16: =IFERROR(B15/B6,0) | C16: =IFERROR(C15/C6,0) | D16: =IFERROR(D15/D6,0) | E16: =IFERROR(E15/E6,0) | F16: =IFERROR(F15/F6,0) | G16: =IFERROR(G15/G6,0) | H16: =IFERROR(H15/H6,0) | I16: =IFERROR(I15/I6,0)
A17: Net interest income / (expense) | B17: =Historical_Data!$B$9 | C17: =Historical_Data!$C$9 | D17: =Historical_Data!$D$9 | E17: =Supporting_Schedules!E25-Supporting_Schedules!E26 | F17: =Supporting_Schedules!F25-Supporting_Schedules!F26 | G17: =Supporting_Schedules!G25-Supporting_Schedules!G26 | H17: =Supporting_Schedules!H25-Supporting_Schedules!H26 | I17: =Supporting_Schedules!I25-Supporting_Schedules!I26
A18: Earnings before tax | B18: =B15+B17 | C18: =C15+C17 | D18: =D15+D17 | E18: =E15+E17 | F18: =F15+F17 | G18: =G15+G17 | H18: =H15+H17 | I18: =I15+I17
A19: Income tax expense / (benefit) | B19: =Historical_Data!$B$10 | C19: =Historical_Data!$C$10 | D19: =Historical_Data!$D$10 | E19: =MAX(0,E18)*Assumptions_and_Inputs!$F$17 | F19: =MAX(0,F18)*Assumptions_and_Inputs!$F$17 | G19: =MAX(0,G18)*Assumptions_and_Inputs!$F$17 | H19: =MAX(0,H18)*Assumptions_and_Inputs!$F$17 | I19: =MAX(0,I18)*Assumptions_and_Inputs!$F$17
A20: Net income | B20: =Historical_Data!$B$11 | C20: =Historical_Data!$C$11 | D20: =Historical_Data!$D$11 | E20: =E18-E19 | F20: =F18-F19 | G20: =G18-G19 | H20: =H18-H19 | I20: =I18-I19
A21: Net income margin | B21: =IFERROR(B20/B6,0) | C21: =IFERROR(C20/C6,0) | D21: =IFERROR(D20/D6,0) | E21: =IFERROR(E20/E6,0) | F21: =IFERROR(F20/F6,0) | G21: =IFERROR(G20/G6,0) | H21: =IFERROR(H20/H6,0) | I21: =IFERROR(I20/I6,0)
A23: Balance sheet (NOK)
A24: Net PP&E | B24: =Historical_Data!B12 | C24: =Historical_Data!C12 | D24: =Historical_Data!D12 | E24: =Supporting_Schedules!E18 | F24: =Supporting_Schedules!F18 | G24: =Supporting_Schedules!G18 | H24: =Supporting_Schedules!H18 | I24: =Supporting_Schedules!I18
A25: Cash and cash equivalents | B25: =Historical_Data!B16 | C25: =Historical_Data!C16 | D25: =Historical_Data!D16 | E25: =E55 | F25: =F55 | G25: =G55 | H25: =H55 | I25: =I55
A26: Accounts receivable | B26: =Historical_Data!B15 | C26: =Historical_Data!C15 | D26: =Historical_Data!D15 | E26: =Supporting_Schedules!E7 | F26: =Supporting_Schedules!F7 | G26: =Supporting_Schedules!G7 | H26: =Supporting_Schedules!H7 | I26: =Supporting_Schedules!I7
A27: Inventory and other operating current assets | B27: =Historical_Data!B13-Historical_Data!B15-Historical_Data!B16 | C27: =Historical_Data!C13-Historical_Data!C15-Historical_Data!C16 | D27: =Historical_Data!D13-Historical_Data!D15-Historical_Data!D16 | E27: =Supporting_Schedules!E8 | F27: =Supporting_Schedules!F8 | G27: =Supporting_Schedules!G8 | H27: =Supporting_Schedules!H8 | I27: =Supporting_Schedules!I8
A28: Total current assets | B28: =SUM(B25:B27) | C28: =SUM(C25:C27) | D28: =SUM(D25:D27) | E28: =SUM(E25:E27) | F28: =SUM(F25:F27) | G28: =SUM(G25:G27) | H28: =SUM(H25:H27) | I28: =SUM(I25:I27)
A29: Total assets | B29: =Historical_Data!B17 | C29: =Historical_Data!C17 | D29: =Historical_Data!D17 | E29: =E24+E28 | F29: =F24+F28 | G29: =G24+G28 | H29: =H24+H28 | I29: =I24+I28
A30: Accounts payable / other current liabilities | B30: =Historical_Data!B18 | C30: =Historical_Data!C18 | D30: =Historical_Data!D18 | E30: =Supporting_Schedules!E9 | F30: =Supporting_Schedules!F9 | G30: =Supporting_Schedules!G9 | H30: =Supporting_Schedules!H9 | I30: =Supporting_Schedules!I9
A31: Long-term debt / revolver | B31: =Historical_Data!B19 | C31: =Historical_Data!C19 | D31: =Historical_Data!D19 | E31: =Supporting_Schedules!E24 | F31: =Supporting_Schedules!F24 | G31: =Supporting_Schedules!G24 | H31: =Supporting_Schedules!H24 | I31: =Supporting_Schedules!I24
A32: Total liabilities | B32: =Historical_Data!B20 | C32: =Historical_Data!C20 | D32: =Historical_Data!D20 | E32: =SUM(E30:E31) | F32: =SUM(F30:F31) | G32: =SUM(G30:G31) | H32: =SUM(H30:H31) | I32: =SUM(I30:I31)
A33: Shareholders' equity | B33: =Historical_Data!B21 | C33: =Historical_Data!C21 | D33: =Historical_Data!D21 | E33: =Supporting_Schedules!E32 | F33: =Supporting_Schedules!F32 | G33: =Supporting_Schedules!G32 | H33: =Supporting_Schedules!H32 | I33: =Supporting_Schedules!I32
A34: Total liabilities and equity | B34: =SUM(B32:B33) | C34: =SUM(C32:C33) | D34: =SUM(D32:D33) | E34: =SUM(E32:E33) | F34: =SUM(F32:F33) | G34: =SUM(G32:G33) | H34: =SUM(H32:H33) | I34: =SUM(I32:I33)
A35: Balance sheet check (assets less claims) | B35: =B29-B34 | C35: =C29-C34 | D35: =D29-D34 | E35: =E29-E34 | F35: =F29-F34 | G35: =G29-G34 | H35: =H29-H34 | I35: =I29-I34
A38: Cash flow statement (NOK)
A39: Net income | B39: ="" | C39: =Historical_Data!C25 | D39: =Historical_Data!D25 | E39: =E20 | F39: =F20 | G39: =G20 | H39: =H20 | I39: =I20
A40: Depreciation and amortization | B40: ="" | C40: =Historical_Data!C26 | D40: =Historical_Data!D26 | E40: =E14 | F40: =F14 | G40: =G14 | H40: =H14 | I40: =I14
A41: Accounts receivable cash-flow impact | B41: ="" | C41: =Historical_Data!C27 | D41: =Historical_Data!D27 | E41: =-Supporting_Schedules!E10 | F41: =-Supporting_Schedules!F10 | G41: =-Supporting_Schedules!G10 | H41: =-Supporting_Schedules!H10 | I41: =-Supporting_Schedules!I10
A42: Inventory / other operating assets cash-flow impact | B42: ="" | C42: =Historical_Data!C28 | D42: =Historical_Data!D28 | E42: =-Supporting_Schedules!E11 | F42: =-Supporting_Schedules!F11 | G42: =-Supporting_Schedules!G11 | H42: =-Supporting_Schedules!H11 | I42: =-Supporting_Schedules!I11
A43: Accounts payable / current liabilities cash-flow impact | B43: ="" | C43: =Historical_Data!C29 | D43: =Historical_Data!D29 | E43: =Supporting_Schedules!E12 | F43: =Supporting_Schedules!F12 | G43: =Supporting_Schedules!G12 | H43: =Supporting_Schedules!H12 | I43: =Supporting_Schedules!I12
...

Sheet Supporting_Schedules
A1: Supporting_Schedules | Working capital, PP&E, debt, and equity roll-forwards
A2: =IF(Model_Checks!$B$2=0,"ALL CHECKS PASSED","MODEL CHECKS FAILED")
A3: Amok Equipment AS | NOK unless stated | Generated 2026-10-10 | Version 1.0
A4: Fiscal year | B4: 2023 | C4: 2024 | D4: 2025 | E4: 2026 | F4: 2027 | G4: 2028 | H4: 2029 | I4: 2030
A6: Working capital schedule (NOK)
A7: Accounts receivable | B7: =Historical_Data!B15 | C7: =Historical_Data!C15 | D7: =Historical_Data!D15 | E7: =IFERROR(Financial_Statements!E6/Assumptions_and_Inputs!$B$24*Assumptions_and_Inputs!$F$10,0) | F7: =IFERROR(Financial_Statements!F6/Assumptions_and_Inputs!$B$24*Assumptions_and_Inputs!$F$10,0) | G7: =IFERROR(Financial_Statements!G6/Assumptions_and_Inputs!$B$24*Assumptions_and_Inputs!$F$10,0) | H7: =IFERROR(Financial_Statements!H6/Assumptions_and_Inputs!$B$24*Assumptions_and_Inputs!$F$10,0) | I7: =IFERROR(Financial_Statements!I6/Assumptions_and_Inputs!$B$24*Assumptions_and_Inputs!$F$10,0)
A8: Inventory and other operating current assets | B8: =Historical_Data!B13-Historical_Data!B15-Historical_Data!B16 | C8: =Historical_Data!C13-Historical_Data!C15-Historical_Data!C16 | D8: =Historical_Data!D13-Historical_Data!D15-Historical_Data!D16 | E8: =IFERROR(Financial_Statements!E8/Assumptions_and_Inputs!$B$24*Assumptions_and_Inputs!$F$11,0) | F8: =IFERROR(Financial_Statements!F8/Assumptions_and_Inputs!$B$24*Assumptions_and_Inputs!$F$11,0) | G8: =IFERROR(Financial_Statements!G8/Assumptions_and_Inputs!$B$24*Assumptions_and_Inputs!$F$11,0) | H8: =IFERROR(Financial_Statements!H8/Assumptions_and_Inputs!$B$24*Assumptions_and_Inputs!$F$11,0) | I8: =IFERROR(Financial_Statements!I8/Assumptions_and_Inputs!$B$24*Assumptions_and_Inputs!$F$11,0)
A9: Accounts payable and other current liabilities (proxy) | B9: =Historical_Data!B18 | C9: =Historical_Data!C18 | D9: =Historical_Data!D18 | E9: =IFERROR(Financial_Statements!E8/Assumptions_and_Inputs!$B$24*Assumptions_and_Inputs!$F$12,0) | F9: =IFERROR(Financial_Statements!F8/Assumptions_and_Inputs!$B$24*Assumptions_and_Inputs!$F$12,0) | G9: =IFERROR(Financial_Statements!G8/Assumptions_and_Inputs!$B$24*Assumptions_and_Inputs!$F$12,0) | H9: =IFERROR(Financial_Statements!H8/Assumptions_and_Inputs!$B$24*Assumptions_and_Inputs!$F$12,0) | I9: =IFERROR(Financial_Statements!I8/Assumptions_and_Inputs!$B$24*Assumptions_and_Inputs!$F$12,0)
A10: Change in accounts receivable (balance change) | B10: ="" | C10: =C7-B7 | D10: =D7-C7 | E10: =E7-D7 | F10: =F7-E7 | G10: =G7-F7 | H10: =H7-G7 | I10: =I7-H7
A11: Change in inventory / other operating assets | B11: ="" | C11: =C8-B8 | D11: =D8-C8 | E11: =E8-D8 | F11: =F8-E8 | G11: =G8-F8 | H11: =H8-G8 | I11: =I8-H8
A12: Change in accounts payable / current liabilities | B12: ="" | C12: =C9-B9 | D12: =D9-C9 | E12: =E9-D9 | F12: =F9-E9 | G12: =G9-F9 | H12: =H9-G9 | I12: =I9-H9
A14: PP&E corkscrew (NOK)
A15: Opening net PP&E | B15: ="" | C15: ="" | D15: ="" | E15: =D18 | F15: =E18 | G15: =F18 | H15: =G18 | I15: =H18
A16: Capital expenditures | B16: ="" | C16: ="" | D16: ="" | E16: =Financial_Statements!E6*Assumptions_and_Inputs!$F$13 | F16: =Financial_Statements!F6*Assumptions_and_Inputs!$F$13 | G16: =Financial_Statements!G6*Assumptions_and_Inputs!$F$13 | H16: =Financial_Statements!H6*Assumptions_and_Inputs!$F$13 | I16: =Financial_Statements!I6*Assumptions_and_Inputs!$F$13
A17: Depreciation and amortization | B17: =Historical_Data!B26 | C17: =Historical_Data!C26 | D17: =Historical_Data!D26 | E17: =MIN(E15+E16,(E15+E16/2)*Assumptions_and_Inputs!$F$14) | F17: =MIN(F15+F16,(F15+F16/2)*Assumptions_and_Inputs!$F$14) | G17: =MIN(G15+G16,(G15+G16/2)*Assumptions_and_Inputs!$F$14) | H17: =MIN(H15+H16,(H15+H16/2)*Assumptions_and_Inputs!$F$14) | I17: =MIN(I15+I16,(I15+I16/2)*Assumptions_and_Inputs!$F$14)
A18: Closing net PP&E | B18: =Historical_Data!B12 | C18: =Historical_Data!C12 | D18: =Historical_Data!D12 | E18: =MAX(0,E15+E16-E17) | F18: =MAX(0,F15+F16-F17) | G18: =MAX(0,G15+G16-G17) | H18: =MAX(0,H15+H16-H17) | I18: =MAX(0,I15+I16-I17)
A20: Revolver and interest (NOK)
A21: Opening revolver debt | B21: ="" | C21: ="" | D21: ="" | E21: =D24 | F21: =E24 | G21: =F24 | H21: =G24 | I21: =H24
A22: Revolver draw | B22: ="" | C22: ="" | D22: ="" | E22: =MIN(MAX(0,Assumptions_and_Inputs!$F$20-E21),MAX(0,Assumptions_and_Inputs!$F$19-(Financial_Statements!D25+Financial_Statements!E45+Financial_Statements!E46+Financial_Statements!E49))) | F22: =MIN(MAX(0,Assumptions_and_Inputs!$F$20-F21),MAX(0,Assumptions_and_Inputs!$F$19-(Financial_Statements!E25+Financial_Statements!F45+Financial_Statements!F46+Financial_Statements!F49))) | G22: =MIN(MAX(0,Assumptions_and_Inputs!$F$20-G21),MAX(0,Assumptions_and_Inputs!$F$19-(Financial_Statements!F25+Financial_Statements!G45+Financial_Statements!G46+Financial_Statements!G49))) | H22: =MIN(MAX(0,Assumptions_and_Inputs!$F$20-H21),MAX(0,Assumptions_and_Inputs!$F$19-(Financial_Statements!G25+Financial_Statements!H45+Financial_Statements!H46+Financial_Statements!H49))) | I22: =MIN(MAX(0,Assumptions_and_Inputs!$F$20-I21),MAX(0,Assumptions_and_Inputs!$F$19-(Financial_Statements!H25+Financial_Statements!I45+Financial_Statements!I46+Financial_Statements!I49)))
A23: Revolver principal repayment | B23: ="" | C23: ="" | D23: ="" | E23: =MIN(E21+E22,MAX(0,Financial_Statements!D25+Financial_Statements!E45+Financial_Statements!E46+Financial_Statements!E49-Assumptions_and_Inputs!$F$19)*Assumptions_and_Inputs!$F$21) | F23: =MIN(F21+F22,MAX(0,Financial_Statements!E25+Financial_Statements!F45+Financial_Statements!F46+Financial_Statements!F49-Assumptions_and_Inputs!$F$19)*Assumptions_and_Inputs!$F$21) | G23: =MIN(G21+G22,MAX(0,Financial_Statements!F25+Financial_Statements!G45+Financial_Statements!G46+Financial_Statements!G49-Assumptions_and_Inputs!$F$19)*Assumptions_and_Inputs!$F$21) | H23: =MIN(H21+H22,MAX(0,Financial_Statements!G25+Financial_Statements!H45+Financial_Statements!H46+Financial_Statements!H49-Assumptions_and_Inputs!$F$19)*Assumptions_and_Inputs!$F$21) | I23: =MIN(I21+I22,MAX(0,Financial_Statements!H25+Financial_Statements!I45+Financial_Statements!I46+Financial_Statements!I49-Assumptions_and_Inputs!$F$19)*Assumptions_and_Inputs!$F$21)
A24: Closing revolver debt | B24: =Historical_Data!B19 | C24: =Historical_Data!C19 | D24: =Historical_Data!D19 | E24: =E21+E22-E23 | F24: =F21+F22-F23 | G24: =G21+G22-G23 | H24: =H21+H22-H23 | I24: =I21+I22-I23
A25: Cash interest income (opening cash method) | B25: ="" | C25: ="" | D25: ="" | E25: =Financial_Statements!D25*Assumptions_and_Inputs!$F$15 | F25: =Financial_Statements!E25*Assumptions_and_Inputs!$F$15 | G25: =Financial_Statements!F25*Assumptions_and_Inputs!$F$15 | H25: =Financial_Statements!G25*Assumptions_and_Inputs!$F$15 | I25: =Financial_Statements!H25*Assumptions_and_Inputs!$F$15
A26: Revolver interest expense (opening debt method) | B26: ="" | C26: ="" | D26: ="" | E26: =E21*Assumptions_and_Inputs!$F$16 | F26: =F21*Assumptions_and_Inputs!$F$16 | G26: =G21*Assumptions_and_Inputs!$F$16 | H26: =H21*Assumptions_and_Inputs!$F$16 | I26: =I21*Assumptions_and_Inputs!$F$16
A28: Shareholders' equity corkscrew (NOK)
A29: Opening shareholders' equity | B29: ="" | C29: ="" | D29: ="" | E29: =D32 | F29: =E32 | G29: =F32 | H29: =G32 | I29: =H32
A30: Net income | B30: =Historical_Data!B11 | C30: =Historical_Data!C11 | D30: =Historical_Data!D11 | E30: =Financial_Statements!E20 | F30: =Financial_Statements!F20 | G30: =Financial_Statements!G20 | H30: =Financial_Statements!H20 | I30: =Financial_Statements!I20
A31: Dividends | B31: ="" | C31: ="" | D31: ="" | E31: =MAX(0,E30)*Assumptions_and_Inputs!$F$18 | F31: =MAX(0,F30)*Assumptions_and_Inputs!$F$18 | G31: =MAX(0,G30)*Assumptions_and_Inputs!$F$18 | H31: =MAX(0,H30)*Assumptions_and_Inputs!$F$18 | I31: =MAX(0,I30)*Assumptions_and_Inputs!$F$18
A32: Closing shareholders' equity | B32: =Historical_Data!B21 | C32: =Historical_Data!C21 | D32: =Historical_Data!D21 | E32: =E29+E30-E31 | F32: =F29+F30-F31 | G32: =G29+G30-G31 | H32: =H29+H30-H31 | I32: =I29+I30-I31

Sheet Scenario_Analysis
A1: Scenario_Analysis | Side-by-side outcomes and forecast schedules by scenario
A2: =IF(Model_Checks!$B$2=0,"ALL CHECKS PASSED","MODEL CHECKS FAILED")
A3: Amok Equipment AS | NOK unless stated | Generated 2026-10-10 | Version 1.0
A4: 2030 output (NOK, except margin) | B4: Base Case | C4: Bull Case | D4: Bear Case | E4: Severe Stress
A5: Revenue | B5: =F15 | C5: =F45 | D5: =F75 | E5: =F105
A6: EBITDA | B6: =F18 | C6: =F48 | D6: =F78 | E6: =F108
A7: EBITDA margin | B7: =IFERROR(B6/B5,0) | C7: =IFERROR(C6/C5,0) | D7: =IFERROR(D6/D5,0) | E7: =IFERROR(E6/E5,0)
A8: Ending cash | B8: =F38 | C8: =F68 | D8: =F98 | E8: =F128
A9: Closing revolver debt | B9: =F37 | C9: =F67 | D9: =F97 | E9: =F127
A10: Liquidity status | B10: =IF(OR(F38<0,F37>Assumptions_and_Inputs!$B$20),"BREACH",IF(F38<Assumptions_and_Inputs!$B$19-Assumptions_and_Inputs!$B$25,"BELOW MIN CASH","PASS")) | C10: =IF(OR(F68<0,F67>Assumptions_and_Inputs!$C$20),"BREACH",IF(F68<Assumptions_and_Inputs!$C$19-Assumptions_and_Inputs!$B$25,"BELOW MIN CASH","PASS")) | D10: =IF(OR(F98<0,F97>Assumptions_and_Inputs!$D$20),"BREACH",IF(F98<Assumptions_and_Inputs!$D$19-Assumptions_and_Inputs!$B$25,"BELOW MIN CASH","PASS")) | E10: =IF(OR(F128<0,F127>Assumptions_and_Inputs!$E$20),"BREACH",IF(F128<Assumptions_and_Inputs!$E$19-Assumptions_and_Inputs!$B$25,"BELOW MIN CASH","PASS"))
A11: Each scenario schedule independently rolls working capital, PP&E, cash, revolver debt, and equity. Liquidity status flags cash shortfalls; active-case details also appear in Financial_Statements.
A13: Base Case | Five-year integrated scenario schedule
A14: Forecast year | B14: 2026 | C14: 2027 | D14: 2028 | E14: 2029 | F14: 2030
A15: Revenue | B15: =Historical_Data!$D$5*(1+Assumptions_and_Inputs!$B$6)*(1+Assumptions_and_Inputs!$B$7) | C15: =B15*(1+Assumptions_and_Inputs!$B$6)*(1+Assumptions_and_Inputs!$B$7) | D15: =C15*(1+Assumptions_and_Inputs!$B$6)*(1+Assumptions_and_Inputs!$B$7) | E15: =D15*(1+Assumptions_and_Inputs!$B$6)*(1+Assumptions_and_Inputs!$B$7) | F15: =E15*(1+Assumptions_and_Inputs!$B$6)*(1+Assumptions_and_Inputs!$B$7)
A16: Non-personnel operating costs | B16: =B15*Assumptions_and_Inputs!$B$8 | C16: =C15*Assumptions_and_Inputs!$B$8 | D16: =D15*Assumptions_and_Inputs!$B$8 | E16: =E15*Assumptions_and_Inputs!$B$8 | F16: =F15*Assumptions_and_Inputs!$B$8
A17: Personnel expenses | B17: =Historical_Data!$D$7*(1+Assumptions_and_Inputs!$B$6)*(1+Assumptions_and_Inputs!$B$9) | C17: =B17*(1+Assumptions_and_Inputs!$B$6)*(1+Assumptions_and_Inputs!$B$9) | D17: =C17*(1+Assumptions_and_Inputs!$B$6)*(1+Assumptions_and_Inputs!$B$9) | E17: =D17*(1+Assumptions_and_Inputs!$B$6)*(1+Assumptions_and_Inputs!$B$9) | F17: =E17*(1+Assumptions_and_Inputs!$B$6)*(1+Assumptions_and_Inputs!$B$9)
A18: EBITDA | B18: =B15-B16-B17 | C18: =C15-C16-C17 | D18: =D15-D16-D17 | E18: =E15-E16-E17 | F18: =F15-F16-F17
A19: Depreciation and amortization | B19: =MIN(B28+B27,(B28+B27/2)*Assumptions_and_Inputs!$B$14) | C19: =MIN(C28+C27,(C28+C27/2)*Assumptions_and_Inputs!$B$14) | D19: =MIN(D28+D27,(D28+D27/2)*Assumptions_and_Inputs!$B$14) | E19: =MIN(E28+E27,(E28+E27/2)*Assumptions_and_Inputs!$B$14) | F19: =MIN(F28+F27,(F28+F27/2)*Assumptions_and_Inputs!$B$14)
A20: EBIT | B20: =B18-B19 | C20: =C18-C19 | D20: =D18-D19 | E20: =E18-E19 | F20: =F18-F19
A21: Cash interest income | B21: =B30*Assumptions_and_Inputs!$B$15 | C21: =C30*Assumptions_and_Inputs!$B$15 | D21: =D30*Assumptions_and_Inputs!$B$15 | E21: =E30*Assumptions_and_Inputs!$B$15 | F21: =F30*Assumptions_and_Inputs!$B$15
A22: Revolver interest expense | B22: =B34*Assumptions_and_Inputs!$B$16 | C22: =C34*Assumptions_and_Inputs!$B$16 | D22: =D34*Assumptions_and_Inputs!$B$16 | E22: =E34*Assumptions_and_Inputs!$B$16 | F22: =F34*Assumptions_and_Inputs!$B$16
A23: Net income | B23: =B20+B21-B22-MAX(0,B20+B21-B22)*Assumptions_and_Inputs!$B$17 | C23: =C20+C21-C22-MAX(0,C20+C21-C22)*Assumptions_and_Inputs!$B$17 | D23: =D20+D21-D22-MAX(0,D20+D21-D22)*Assumptions_and_Inputs!$B$17 | E23: =E20+E21-E22-MAX(0,E20+E21-E22)*Assumptions_and_Inputs!$B$17 | F23: =F20+F21-F22-MAX(0,F20+F21-F22)*Assumptions_and_Inputs!$B$17
A24: Accounts receivable | B24: =IFERROR(B15/Assumptions_and_Inputs!$B$24*Assumptions_and_Inputs!$B$10,0) | C24: =IFERROR(C15/Assumptions_and_Inputs!$B$24*Assumptions_and_Inputs!$B$10,0) | D24: =IFERROR(D15/Assumptions_and_Inputs!$B$24*Assumptions_and_Inputs!$B$10,0) | E24: =IFERROR(E15/Assumptions_and_Inputs!$B$24*Assumptions_and_Inputs!$B$10,0) | F24: =IFERROR(F15/Assumptions_and_Inputs!$B$24*Assumptions_and_Inputs!$B$10,0)
A25: Inventory and other operating assets | B25: =IFERROR(B16/Assumptions_and_Inputs!$B$24*Assumptions_and_Inputs!$B$11,0) | C25: =IFERROR(C16/Assumptions_and_Inputs!$B$24*Assumptions_and_Inputs!$B$11,0) | D25: =IFERROR(D16/Assumptions_and_Inputs!$B$24*Assumptions_and_Inputs!$B$11,0) | E25: =IFERROR(E16/Assumptions_and_Inputs!$B$24*Assumptions_and_Inputs!$B$11,0) | F25: =IFERROR(F16/Assumptions_and_Inputs!$B$24*Assumptions_and_Inputs!$B$11,0)
A26: Accounts payable / current liabilities | B26: =IFERROR(B16/Assumptions_and_Inputs!$B$24*Assumptions_and_Inputs!$B$12,0) | C26: =IFERROR(C16/Assumptions_and_Inputs!$B$24*Assumptions_and_Inputs!$B$12,0) | D26: =IFERROR(D16/Assumptions_and_Inputs!$B$24*Assumptions_and_Inputs!$B$12,0) | E26: =IFERROR(E16/Assumptions_and_Inputs!$B$24*Assumptions_and_Inputs!$B$12,0) | F26: =IFERROR(F16/Assumptions_and_Inputs!$B$24*Assumptions_and_Inputs!$B$12,0)
A27: Capital expenditure | B27: =B15*Assumptions_and_Inputs!$B$13 | C27: =C15*Assumptions_and_Inputs!$B$13 | D27: =D15*Assumptions_and_Inputs!$B$13 | E27: =E15*Assumptions_and_Inputs!$B$13 | F27: =F15*Assumptions_and_Inputs!$B$13
A28: Opening net PP&E | B28: =Historical_Data!$D$12 | C28: =B29 | D28: =C29 | E28: =D29 | F28: =E29
A29: Closing net PP&E | B29: =MAX(0,B28+B27-B19) | C29: =MAX(0,C28+C27-C19) | D29: =MAX(0,D28+D27-D19) | E29: =MAX(0,E28+E27-E19) | F29: =MAX(0,F28+F27-F19)
A30: Opening cash | B30: =Historical_Data!$D$16 | C30: =B38 | D30: =C38 | E30: =D38 | F30: =E38
A31: Cash from operations | B31: =B23+B19-(B24-Historical_Data!$D$15)-(B25-(Historical_Data!$D$13-Historical_Data!$D$15-Historical_Data!$D$16))+(B26-Historical_Data!$D$18) | C31: =C23+C19-(C24-B24)-(C25-B25)+(C26-B26) | D31: =D23+D19-(D24-C24)-(D25-C25)+(D26-C26) | E31: =E23+E19-(E24-D24)-(E25-D25)+(E26-D26) | F31: =F23+F19-(F24-E24)-(F25-E25)+(F26-E26)
A32: Dividends | B32: =MAX(0,B23)*Assumptions_and_Inputs!$B$18 | C32: =MAX(0,C23)*Assumptions_and_Inputs!$B$18 | D32: =MAX(0,D23)*Assumptions_and_Inputs!$B$18 | E32: =MAX(0,E23)*Assumptions_and_Inputs!$B$18 | F32: =MAX(0,F23)*Assumptions_and_Inputs!$B$18
A33: Cash before financing | B33: =B30+B31-B27-B32 | C33: =C30+C31-C27-C32 | D33: =D30+D31-D27-D32 | E33: =E30+E31-E27-E32 | F33: =F30+F31-F27-F32
A34: Opening revolver debt | B34: =IFERROR(Historical_Data!$D$19,0) | C34: =B37 | D34: =C37 | E34: =D37 | F34: =E37
A35: Revolver draw | B35: =MIN(MAX(0,Assumptions_and_Inputs!$B$20-B34),MAX(0,Assumptions_and_Inputs!$B$19-B33)) | C35: =MIN(MAX(0,Assumptions_and_Inputs!$B$20-C34),MAX(0,Assumptions_and_Inputs!$B$19-C33)) | D35: =MIN(MAX(0,Assumptions_and_Inputs!$B$20-D34),MAX(0,Assumptions_and_Inputs!$B$19-D33)) | E35: =MIN(MAX(0,Assumptions_and_Inputs!$B$20-E34),MAX(0,Assumptions_and_Inputs!$B$19-E33)) | F35: =MIN(MAX(0,Assumptions_and_Inputs!$B$20-F34),MAX(0,Assumptions_and_Inputs!$B$19-F33))
A36: Revolver repayment | B36: =MIN(B34+B35,MAX(0,B33-Assumptions_and_Inputs!$B$19)*Assumptions_and_Inputs!$B$21) | C36: =MIN(C34+C35,MAX(0,C33-Assumptions_and_Inputs!$B$19)*Assumptions_and_Inputs!$B$21) | D36: =MIN(D34+D35,MAX(0,D33-Assumptions_and_Inputs!$B$19)*Assumptions_and_Inputs!$B$21) | E36: =MIN(E34+E35,MAX(0,E33-Assumptions_and_Inputs!$B$19)*Assumptions_and_Inputs!$B$21) | F36: =MIN(F34+F35,MAX(0,F33-Assumptions_and_Inputs!$B$19)*Assumptions_and_Inputs!$B$21)
A37: Closing revolver debt | B37: =B34+B35-B36 | C37: =C34+C35-C36 | D37: =D34+D35-D36 | E37: =E34+E35-E36 | F37: =F34+F35-F36
A38: Ending cash | B38: =B33+B35-B36 | C38: =C33+C35-C36 | D38: =D33+D35-D36 | E38: =E33+E35-E36 | F38: =F33+F35-F36
A39: Opening shareholders' equity | B39: =Historical_Data!$D$21 | C39: =B40 | D39: =C40 | E39: =D40 | F39: =E40
A40: Closing shareholders' equity | B40: =B39+B23-B32 | C40: =C39+C23-C32 | D40: =D39+D23-D32 | E40: =E39+E23-E32 | F40: =F39+F23-F32
A41: Balance sheet difference | B41: =B38+B24+B25+B29-B26-B37-B40 | C41: =C38+C24+C25+C29-C26-C37-C40 | D41: =D38+D24+D25+D29-D26-D37-D40 | E41: =E38+E24+E25+E29-E26-E37-E40 | F41: =F38+F24+F25+F29-F26-F37-F40
...

Sheet Sensitivity_Analysis
A1: Sensitivity_Analysis | 2030 EBITDA scenario and driver sensitivity
A2: =IF(Model_Checks!$B$2=0,"ALL CHECKS PASSED","MODEL CHECKS FAILED")
A3: Amok Equipment AS | NOK unless stated | Generated 2026-10-10 | Version 1.0
A4: Two-way sensitivity | 2030 EBITDA (NOK)
A5: Cost ratio shocks (editable) | B5: Input offset | C5: -0.05 | D5: -0.025 | E5: 0 | F5: 0.025 | G5: 0.05
A6: Volume growth Δ / Non-personnel cost ratio | C6: =Assumptions_and_Inputs!$F$8+C$5 | D6: =Assumptions_and_Inputs!$F$8+D$5 | E6: =Assumptions_and_Inputs!$F$8+E$5 | F6: =Assumptions_and_Inputs!$F$8+F$5 | G6: =Assumptions_and_Inputs!$F$8+G$5
B7: -0.1 | C7: =IFERROR(Historical_Data!$D$5*(1+Assumptions_and_Inputs!$F$6+$B7)^Assumptions_and_Inputs!$B$26*(1+Assumptions_and_Inputs!$F$7)^Assumptions_and_Inputs!$B$26*(1-C$6)-Historical_Data!$D$7*(1+Assumptions_and_Inputs!$F$6+$B7)^Assumptions_and_Inputs!$B$26*(1+Assumptions_and_Inputs!$F$9)^Assumptions_and_Inputs!$B$26,0) | D7: =IFERROR(Historical_Data!$D$5*(1+Assumptions_and_Inputs!$F$6+$B7)^Assumptions_and_Inputs!$B$26*(1+Assumptions_and_Inputs!$F$7)^Assumptions_and_Inputs!$B$26*(1-D$6)-Historical_Data!$D$7*(1+Assumptions_and_Inputs!$F$6+$B7)^Assumptions_and_Inputs!$B$26*(1+Assumptions_and_Inputs!$F$9)^Assumptions_and_Inputs!$B$26,0) | E7: =IFERROR(Historical_Data!$D$5*(1+Assumptions_and_Inputs!$F$6+$B7)^Assumptions_and_Inputs!$B$26*(1+Assumptions_and_Inputs!$F$7)^Assumptions_and_Inputs!$B$26*(1-E$6)-Historical_Data!$D$7*(1+Assumptions_and_Inputs!$F$6+$B7)^Assumptions_and_Inputs!$B$26*(1+Assumptions_and_Inputs!$F$9)^Assumptions_and_Inputs!$B$26,0) | F7: =IFERROR(Historical_Data!$D$5*(1+Assumptions_and_Inputs!$F$6+$B7)^Assumptions_and_Inputs!$B$26*(1+Assumptions_and_Inputs!$F$7)^Assumptions_and_Inputs!$B$26*(1-F$6)-Historical_Data!$D$7*(1+Assumptions_and_Inputs!$F$6+$B7)^Assumptions_and_Inputs!$B$26*(1+Assumptions_and_Inputs!$F$9)^Assumptions_and_Inputs!$B$26,0) | G7: =IFERROR(Historical_Data!$D$5*(1+Assumptions_and_Inputs!$F$6+$B7)^Assumptions_and_Inputs!$B$26*(1+Assumptions_and_Inputs!$F$7)^Assumptions_and_Inputs!$B$26*(1-G$6)-Historical_Data!$D$7*(1+Assumptions_and_Inputs!$F$6+$B7)^Assumptions_and_Inputs!$B$26*(1+Assumptions_and_Inputs!$F$9)^Assumptions_and_Inputs!$B$26,0)
B8: -0.05 | C8: =IFERROR(Historical_Data!$D$5*(1+Assumptions_and_Inputs!$F$6+$B8)^Assumptions_and_Inputs!$B$26*(1+Assumptions_and_Inputs!$F$7)^Assumptions_and_Inputs!$B$26*(1-C$6)-Historical_Data!$D$7*(1+Assumptions_and_Inputs!$F$6+$B8)^Assumptions_and_Inputs!$B$26*(1+Assumptions_and_Inputs!$F$9)^Assumptions_and_Inputs!$B$26,0) | D8: =IFERROR(Historical_Data!$D$5*(1+Assumptions_and_Inputs!$F$6+$B8)^Assumptions_and_Inputs!$B$26*(1+Assumptions_and_Inputs!$F$7)^Assumptions_and_Inputs!$B$26*(1-D$6)-Historical_Data!$D$7*(1+Assumptions_and_Inputs!$F$6+$B8)^Assumptions_and_Inputs!$B$26*(1+Assumptions_and_Inputs!$F$9)^Assumptions_and_Inputs!$B$26,0) | E8: =IFERROR(Historical_Data!$D$5*(1+Assumptions_and_Inputs!$F$6+$B8)^Assumptions_and_Inputs!$B$26*(1+Assumptions_and_Inputs!$F$7)^Assumptions_and_Inputs!$B$26*(1-E$6)-Historical_Data!$D$7*(1+Assumptions_and_Inputs!$F$6+$B8)^Assumptions_and_Inputs!$B$26*(1+Assumptions_and_Inputs!$F$9)^Assumptions_and_Inputs!$B$26,0) | F8: =IFERROR(Historical_Data!$D$5*(1+Assumptions_and_Inputs!$F$6+$B8)^Assumptions_and_Inputs!$B$26*(1+Assumptions_and_Inputs!$F$7)^Assumptions_and_Inputs!$B$26*(1-F$6)-Historical_Data!$D$7*(1+Assumptions_and_Inputs!$F$6+$B8)^Assumptions_and_Inputs!$B$26*(1+Assumptions_and_Inputs!$F$9)^Assumptions_and_Inputs!$B$26,0) | G8: =IFERROR(Historical_Data!$D$5*(1+Assumptions_and_Inputs!$F$6+$B8)^Assumptions_and_Inputs!$B$26*(1+Assumptions_and_Inputs!$F$7)^Assumptions_and_Inputs!$B$26*(1-G$6)-Historical_Data!$D$7*(1+Assumptions_and_Inputs!$F$6+$B8)^Assumptions_and_Inputs!$B$26*(1+Assumptions_and_Inputs!$F$9)^Assumptions_and_Inputs!$B$26,0)
B9: 0 | C9: =IFERROR(Historical_Data!$D$5*(1+Assumptions_and_Inputs!$F$6+$B9)^Assumptions_and_Inputs!$B$26*(1+Assumptions_and_Inputs!$F$7)^Assumptions_and_Inputs!$B$26*(1-C$6)-Historical_Data!$D$7*(1+Assumptions_and_Inputs!$F$6+$B9)^Assumptions_and_Inputs!$B$26*(1+Assumptions_and_Inputs!$F$9)^Assumptions_and_Inputs!$B$26,0) | D9: =IFERROR(Historical_Data!$D$5*(1+Assumptions_and_Inputs!$F$6+$B9)^Assumptions_and_Inputs!$B$26*(1+Assumptions_and_Inputs!$F$7)^Assumptions_and_Inputs!$B$26*(1-D$6)-Historical_Data!$D$7*(1+Assumptions_and_Inputs!$F$6+$B9)^Assumptions_and_Inputs!$B$26*(1+Assumptions_and_Inputs!$F$9)^Assumptions_and_Inputs!$B$26,0) | E9: =IFERROR(Historical_Data!$D$5*(1+Assumptions_and_Inputs!$F$6+$B9)^Assumptions_and_Inputs!$B$26*(1+Assumptions_and_Inputs!$F$7)^Assumptions_and_Inputs!$B$26*(1-E$6)-Historical_Data!$D$7*(1+Assumptions_and_Inputs!$F$6+$B9)^Assumptions_and_Inputs!$B$26*(1+Assumptions_and_Inputs!$F$9)^Assumptions_and_Inputs!$B$26,0) | F9: =IFERROR(Historical_Data!$D$5*(1+Assumptions_and_Inputs!$F$6+$B9)^Assumptions_and_Inputs!$B$26*(1+Assumptions_and_Inputs!$F$7)^Assumptions_and_Inputs!$B$26*(1-F$6)-Historical_Data!$D$7*(1+Assumptions_and_Inputs!$F$6+$B9)^Assumptions_and_Inputs!$B$26*(1+Assumptions_and_Inputs!$F$9)^Assumptions_and_Inputs!$B$26,0) | G9: =IFERROR(Historical_Data!$D$5*(1+Assumptions_and_Inputs!$F$6+$B9)^Assumptions_and_Inputs!$B$26*(1+Assumptions_and_Inputs!$F$7)^Assumptions_and_Inputs!$B$26*(1-G$6)-Historical_Data!$D$7*(1+Assumptions_and_Inputs!$F$6+$B9)^Assumptions_and_Inputs!$B$26*(1+Assumptions_and_Inputs!$F$9)^Assumptions_and_Inputs!$B$26,0)
B10: 0.05 | C10: =IFERROR(Historical_Data!$D$5*(1+Assumptions_and_Inputs!$F$6+$B10)^Assumptions_and_Inputs!$B$26*(1+Assumptions_and_Inputs!$F$7)^Assumptions_and_Inputs!$B$26*(1-C$6)-Historical_Data!$D$7*(1+Assumptions_and_Inputs!$F$6+$B10)^Assumptions_and_Inputs!$B$26*(1+Assumptions_and_Inputs!$F$9)^Assumptions_and_Inputs!$B$26,0) | D10: =IFERROR(Historical_Data!$D$5*(1+Assumptions_and_Inputs!$F$6+$B10)^Assumptions_and_Inputs!$B$26*(1+Assumptions_and_Inputs!$F$7)^Assumptions_and_Inputs!$B$26*(1-D$6)-Historical_Data!$D$7*(1+Assumptions_and_Inputs!$F$6+$B10)^Assumptions_and_Inputs!$B$26*(1+Assumptions_and_Inputs!$F$9)^Assumptions_and_Inputs!$B$26,0) | E10: =IFERROR(Historical_Data!$D$5*(1+Assumptions_and_Inputs!$F$6+$B10)^Assumptions_and_Inputs!$B$26*(1+Assumptions_and_Inputs!$F$7)^Assumptions_and_Inputs!$B$26*(1-E$6)-Historical_Data!$D$7*(1+Assumptions_and_Inputs!$F$6+$B10)^Assumptions_and_Inputs!$B$26*(1+Assumptions_and_Inputs!$F$9)^Assumptions_and_Inputs!$B$26,0) | F10: =IFERROR(Historical_Data!$D$5*(1+Assumptions_and_Inputs!$F$6+$B10)^Assumptions_and_Inputs!$B$26*(1+Assumptions_and_Inputs!$F$7)^Assumptions_and_Inputs!$B$26*(1-F$6)-Historical_Data!$D$7*(1+Assumptions_and_Inputs!$F$6+$B10)^Assumptions_and_Inputs!$B$26*(1+Assumptions_and_Inputs!$F$9)^Assumptions_and_Inputs!$B$26,0) | G10: =IFERROR(Historical_Data!$D$5*(1+Assumptions_and_Inputs!$F$6+$B10)^Assumptions_and_Inputs!$B$26*(1+Assumptions_and_Inputs!$F$7)^Assumptions_and_Inputs!$B$26*(1-G$6)-Historical_Data!$D$7*(1+Assumptions_and_Inputs!$F$6+$B10)^Assumptions_and_Inputs!$B$26*(1+Assumptions_and_Inputs!$F$9)^Assumptions_and_Inputs!$B$26,0)
B11: 0.1 | C11: =IFERROR(Historical_Data!$D$5*(1+Assumptions_and_Inputs!$F$6+$B11)^Assumptions_and_Inputs!$B$26*(1+Assumptions_and_Inputs!$F$7)^Assumptions_and_Inputs!$B$26*(1-C$6)-Historical_Data!$D$7*(1+Assumptions_and_Inputs!$F$6+$B11)^Assumptions_and_Inputs!$B$26*(1+Assumptions_and_Inputs!$F$9)^Assumptions_and_Inputs!$B$26,0) | D11: =IFERROR(Historical_Data!$D$5*(1+Assumptions_and_Inputs!$F$6+$B11)^Assumptions_and_Inputs!$B$26*(1+Assumptions_and_Inputs!$F$7)^Assumptions_and_Inputs!$B$26*(1-D$6)-Historical_Data!$D$7*(1+Assumptions_and_Inputs!$F$6+$B11)^Assumptions_and_Inputs!$B$26*(1+Assumptions_and_Inputs!$F$9)^Assumptions_and_Inputs!$B$26,0) | E11: =IFERROR(Historical_Data!$D$5*(1+Assumptions_and_Inputs!$F$6+$B11)^Assumptions_and_Inputs!$B$26*(1+Assumptions_and_Inputs!$F$7)^Assumptions_and_Inputs!$B$26*(1-E$6)-Historical_Data!$D$7*(1+Assumptions_and_Inputs!$F$6+$B11)^Assumptions_and_Inputs!$B$26*(1+Assumptions_and_Inputs!$F$9)^Assumptions_and_Inputs!$B$26,0) | F11: =IFERROR(Historical_Data!$D$5*(1+Assumptions_and_Inputs!$F$6+$B11)^Assumptions_and_Inputs!$B$26*(1+Assumptions_and_Inputs!$F$7)^Assumptions_and_Inputs!$B$26*(1-F$6)-Historical_Data!$D$7*(1+Assumptions_and_Inputs!$F$6+$B11)^Assumptions_and_Inputs!$B$26*(1+Assumptions_and_Inputs!$F$9)^Assumptions_and_Inputs!$B$26,0) | G11: =IFERROR(Historical_Data!$D$5*(1+Assumptions_and_Inputs!$F$6+$B11)^Assumptions_and_Inputs!$B$26*(1+Assumptions_and_Inputs!$F$7)^Assumptions_and_Inputs!$B$26*(1-G$6)-Historical_Data!$D$7*(1+Assumptions_and_Inputs!$F$6+$B11)^Assumptions_and_Inputs!$B$26*(1+Assumptions_and_Inputs!$F$9)^Assumptions_and_Inputs!$B$26,0)
A13: Base case tie-out | B13: =IFERROR(Financial_Statements!$I$12,0) | C13: Sensitivity center | D13: =E9 | E13: Difference | F13: =D13-B13
A15: One-way tornado | Change in 2030 EBITDA (NOK)
A16: Driver | B16: Downside EBITDA | C16: Upside EBITDA | D16: Downside impact | E16: Upside impact | F16: Elasticity | G16: Downside shock | H16: Upside shock
A17: Volume growth | B17: =IFERROR(Historical_Data!$D$5*(1+(Assumptions_and_Inputs!$F$6+$G17))^Assumptions_and_Inputs!$B$26*(1+Assumptions_and_Inputs!$F$7)^Assumptions_and_Inputs!$B$26*(1-Assumptions_and_Inputs!$F$8)-Historical_Data!$D$7*(1+(Assumptions_and_Inputs!$F$6+$G17))^Assumptions_and_Inputs!$B$26*(1+Assumptions_and_Inputs!$F$9)^Assumptions_and_Inputs!$B$26,0) | C17: =IFERROR(Historical_Data!$D$5*(1+(Assumptions_and_Inputs!$F$6+$H17))^Assumptions_and_Inputs!$B$26*(1+Assumptions_and_Inputs!$F$7)^Assumptions_and_Inputs!$B$26*(1-Assumptions_and_Inputs!$F$8)-Historical_Data!$D$7*(1+(Assumptions_and_Inputs!$F$6+$H17))^Assumptions_and_Inputs!$B$26*(1+Assumptions_and_Inputs!$F$9)^Assumptions_and_Inputs!$B$26,0) | D17: =B17-$B$13 | E17: =C17-$B$13 | F17: =IFERROR(((C17-B17)/$B$13)/(($H17-$G17)/Assumptions_and_Inputs!$F$6),0) | G17: -0.05 | H17: 0.05
A18: Price realization growth | B18: =IFERROR(Historical_Data!$D$5*(1+Assumptions_and_Inputs!$F$6)^Assumptions_and_Inputs!$B$26*(1+(Assumptions_and_Inputs!$F$7+$G18))^Assumptions_and_Inputs!$B$26*(1-Assumptions_and_Inputs!$F$8)-Historical_Data!$D$7*(1+Assumptions_and_Inputs!$F$6)^Assumptions_and_Inputs!$B$26*(1+Assumptions_and_Inputs!$F$9)^Assumptions_and_Inputs!$B$26,0) | C18: =IFERROR(Historical_Data!$D$5*(1+Assumptions_and_Inputs!$F$6)^Assumptions_and_Inputs!$B$26*(1+(Assumptions_and_Inputs!$F$7+$H18))^Assumptions_and_Inputs!$B$26*(1-Assumptions_and_Inputs!$F$8)-Historical_Data!$D$7*(1+Assumptions_and_Inputs!$F$6)^Assumptions_and_Inputs!$B$26*(1+Assumptions_and_Inputs!$F$9)^Assumptions_and_Inputs!$B$26,0) | D18: =B18-$B$13 | E18: =C18-$B$13 | F18: =IFERROR(((C18-B18)/$B$13)/(($H18-$G18)/Assumptions_and_Inputs!$F$7),0) | G18: -0.02 | H18: 0.02
A19: Non-personnel cost ratio | B19: =IFERROR(Historical_Data!$D$5*(1+Assumptions_and_Inputs!$F$6)^Assumptions_and_Inputs!$B$26*(1+Assumptions_and_Inputs!$F$7)^Assumptions_and_Inputs!$B$26*(1-(Assumptions_and_Inputs!$F$8+$G19))-Historical_Data!$D$7*(1+Assumptions_and_Inputs!$F$6)^Assumptions_and_Inputs!$B$26*(1+Assumptions_and_Inputs!$F$9)^Assumptions_and_Inputs!$B$26,0) | C19: =IFERROR(Historical_Data!$D$5*(1+Assumptions_and_Inputs!$F$6)^Assumptions_and_Inputs!$B$26*(1+Assumptions_and_Inputs!$F$7)^Assumptions_and_Inputs!$B$26*(1-(Assumptions_and_Inputs!$F$8+$H19))-Historical_Data!$D$7*(1+Assumptions_and_Inputs!$F$6)^Assumptions_and_Inputs!$B$26*(1+Assumptions_and_Inputs!$F$9)^Assumptions_and_Inputs!$B$26,0) | D19: =B19-$B$13 | E19: =C19-$B$13 | F19: =IFERROR(((C19-B19)/$B$13)/(($H19-$G19)/Assumptions_and_Inputs!$F$8),0) | G19: 0.03 | H19: -0.03
A20: Wage inflation | B20: =IFERROR(Historical_Data!$D$5*(1+Assumptions_and_Inputs!$F$6)^Assumptions_and_Inputs!$B$26*(1+Assumptions_and_Inputs!$F$7)^Assumptions_and_Inputs!$B$26*(1-Assumptions_and_Inputs!$F$8)-Historical_Data!$D$7*(1+Assumptions_and_Inputs!$F$6)^Assumptions_and_Inputs!$B$26*(1+(Assumptions_and_Inputs!$F$9+$G20))^Assumptions_and_Inputs!$B$26,0) | C20: =IFERROR(Historical_Data!$D$5*(1+Assumptions_and_Inputs!$F$6)^Assumptions_and_Inputs!$B$26*(1+Assumptions_and_Inputs!$F$7)^Assumptions_and_Inputs!$B$26*(1-Assumptions_and_Inputs!$F$8)-Historical_Data!$D$7*(1+Assumptions_and_Inputs!$F$6)^Assumptions_and_Inputs!$B$26*(1+(Assumptions_and_Inputs!$F$9+$H20))^Assumptions_and_Inputs!$B$26,0) | D20: =B20-$B$13 | E20: =C20-$B$13 | F20: =IFERROR(((C20-B20)/$B$13)/(($H20-$G20)/Assumptions_and_Inputs!$F$9),0) | G20: 0.02 | H20: -0.02
A23: Tornado shocks are one-at-a-time changes around the active scenario. Elasticity is the percentage change in EBITDA divided by the percentage change in the driver across the full downside-to-upside range.

Sheet Model_Checks
A1: Model_Checks | Accounting, roll-forward, scenario, and sensitivity assertions
A2: =IF(B2=0,"ALL CHECKS PASSED","MODEL CHECKS FAILED") | B2: =SUM(K6:K17)
A3: Amok Equipment AS | NOK unless stated | Generated 2026-10-10 | Version 1.0
A4: Failed checks (zero is pass) | B4: =SUM(K6:K17)
A5: Check | B5: Test | C5: 2023 | D5: 2024 | E5: 2025 | F5: 2026 | G5: 2027 | H5: 2028 | I5: 2029 | J5: 2030 | K5: Total failures
A6: Balance sheet equilibrium | B6: Assets equal liabilities plus equity within the centralized NOK tolerance. | C6: =IF(ABS(Financial_Statements!B35)<=Assumptions_and_Inputs!$B$25,0,1) | D6: =IF(ABS(Financial_Statements!C35)<=Assumptions_and_Inputs!$B$25,0,1) | E6: =IF(ABS(Financial_Statements!D35)<=Assumptions_and_Inputs!$B$25,0,1) | F6: =IF(ABS(Financial_Statements!E35)<=Assumptions_and_Inputs!$B$25,0,1) | G6: =IF(ABS(Financial_Statements!F35)<=Assumptions_and_Inputs!$B$25,0,1) | H6: =IF(ABS(Financial_Statements!G35)<=Assumptions_and_Inputs!$B$25,0,1) | I6: =IF(ABS(Financial_Statements!H35)<=Assumptions_and_Inputs!$B$25,0,1) | J6: =IF(ABS(Financial_Statements!I35)<=Assumptions_and_Inputs!$B$25,0,1) | K6: =SUM(C6:J6)
A7: Cash reconciliation | B7: Cash flow ending cash agrees with balance sheet cash. | C7: =0 | D7: =IF(ABS(Financial_Statements!C55-Financial_Statements!C25)<=Assumptions_and_Inputs!$B$25,0,1) | E7: =IF(ABS(Financial_Statements!D55-Financial_Statements!D25)<=Assumptions_and_Inputs!$B$25,0,1) | F7: =IF(ABS(Financial_Statements!E55-Financial_Statements!E25)<=Assumptions_and_Inputs!$B$25,0,1) | G7: =IF(ABS(Financial_Statements!F55-Financial_Statements!F25)<=Assumptions_and_Inputs!$B$25,0,1) | H7: =IF(ABS(Financial_Statements!G55-Financial_Statements!G25)<=Assumptions_and_Inputs!$B$25,0,1) | I7: =IF(ABS(Financial_Statements!H55-Financial_Statements!H25)<=Assumptions_and_Inputs!$B$25,0,1) | J7: =IF(ABS(Financial_Statements!I55-Financial_Statements!I25)<=Assumptions_and_Inputs!$B$25,0,1) | K7: =SUM(C7:J7)
A8: Equity roll-forward | B8: Forecast equity equals opening equity + net income - dividends. | C8: =0 | D8: =0 | E8: =0 | F8: =IF(ABS(Supporting_Schedules!E32-(Supporting_Schedules!E29+Supporting_Schedules!E30-Supporting_Schedules!E31))<=Assumptions_and_Inputs!$B$25,0,1) | G8: =IF(ABS(Supporting_Schedules!F32-(Supporting_Schedules!F29+Supporting_Schedules!F30-Supporting_Schedules!F31))<=Assumptions_and_Inputs!$B$25,0,1) | H8: =IF(ABS(Supporting_Schedules!G32-(Supporting_Schedules!G29+Supporting_Schedules!G30-Supporting_Schedules!G31))<=Assumptions_and_Inputs!$B$25,0,1) | I8: =IF(ABS(Supporting_Schedules!H32-(Supporting_Schedules!H29+Supporting_Schedules!H30-Supporting_Schedules!H31))<=Assumptions_and_Inputs!$B$25,0,1) | J8: =IF(ABS(Supporting_Schedules!I32-(Supporting_Schedules!I29+Supporting_Schedules!I30-Supporting_Schedules!I31))<=Assumptions_and_Inputs!$B$25,0,1) | K8: =SUM(C8:J8)
A9: PP&E roll-forward | B9: Forecast PP&E equals opening PP&E + CapEx - D&A. | C9: =0 | D9: =0 | E9: =0 | F9: =IF(ABS(Supporting_Schedules!E18-(Supporting_Schedules!E15+Supporting_Schedules!E16-Supporting_Schedules!E17))<=Assumptions_and_Inputs!$B$25,0,1) | G9: =IF(ABS(Supporting_Schedules!F18-(Supporting_Schedules!F15+Supporting_Schedules!F16-Supporting_Schedules!F17))<=Assumptions_and_Inputs!$B$25,0,1) | H9: =IF(ABS(Supporting_Schedules!G18-(Supporting_Schedules!G15+Supporting_Schedules!G16-Supporting_Schedules!G17))<=Assumptions_and_Inputs!$B$25,0,1) | I9: =IF(ABS(Supporting_Schedules!H18-(Supporting_Schedules!H15+Supporting_Schedules!H16-Supporting_Schedules!H17))<=Assumptions_and_Inputs!$B$25,0,1) | J9: =IF(ABS(Supporting_Schedules!I18-(Supporting_Schedules!I15+Supporting_Schedules!I16-Supporting_Schedules!I17))<=Assumptions_and_Inputs!$B$25,0,1) | K9: =SUM(C9:J9)
A10: Debt roll-forward / facility | B10: Debt rolls forward correctly and remains within facility; cash is not negative. | C10: =0 | D10: =0 | E10: =0 | F10: =IF(OR(ABS(Supporting_Schedules!E24-(Supporting_Schedules!E21+Supporting_Schedules!E22-Supporting_Schedules!E23))>Assumptions_and_Inputs!$B$25,Supporting_Schedules!E24>Assumptions_and_Inputs!$F$20+Assumptions_and_Inputs!$B$25,Financial_Statements!E25<0,AND(Financial_Statements!E25<Assumptions_and_Inputs!$F$19-Assumptions_and_Inputs!$B$25,Supporting_Schedules!E24<Assumptions_and_Inputs!$F$20-Assumptions_and_Inputs!$B$25)),1,0) | G10: =IF(OR(ABS(Supporting_Schedules!F24-(Supporting_Schedules!F21+Supporting_Schedules!F22-Supporting_Schedules!F23))>Assumptions_and_Inputs!$B$25,Supporting_Schedules!F24>Assumptions_and_Inputs!$F$20+Assumptions_and_Inputs!$B$25,Financial_Statements!F25<0,AND(Financial_Statements!F25<Assumptions_and_Inputs!$F$19-Assumptions_and_Inputs!$B$25,Supporting_Schedules!F24<Assumptions_and_Inputs!$F$20-Assumptions_and_Inputs!$B$25)),1,0) | H10: =IF(OR(ABS(Supporting_Schedules!G24-(Supporting_Schedules!G21+Supporting_Schedules!G22-Supporting_Schedules!G23))>Assumptions_and_Inputs!$B$25,Supporting_Schedules!G24>Assumptions_and_Inputs!$F$20+Assumptions_and_Inputs!$B$25,Financial_Statements!G25<0,AND(Financial_Statements!G25<Assumptions_and_Inputs!$F$19-Assumptions_and_Inputs!$B$25,Supporting_Schedules!G24<Assumptions_and_Inputs!$F$20-Assumptions_and_Inputs!$B$25)),1,0) | I10: =IF(OR(ABS(Supporting_Schedules!H24-(Supporting_Schedules!H21+Supporting_Schedules!H22-Supporting_Schedules!H23))>Assumptions_and_Inputs!$B$25,Supporting_Schedules!H24>Assumptions_and_Inputs!$F$20+Assumptions_and_Inputs!$B$25,Financial_Statements!H25<0,AND(Financial_Statements!H25<Assumptions_and_Inputs!$F$19-Assumptions_and_Inputs!$B$25,Supporting_Schedules!H24<Assumptions_and_Inputs!$F$20-Assumptions_and_Inputs!$B$25)),1,0) | J10: =IF(OR(ABS(Supporting_Schedules!I24-(Supporting_Schedules!I21+Supporting_Schedules!I22-Supporting_Schedules!I23))>Assumptions_and_Inputs!$B$25,Supporting_Schedules!I24>Assumptions_and_Inputs!$F$20+Assumptions_and_Inputs!$B$25,Financial_Statements!I25<0,AND(Financial_Statements!I25<Assumptions_and_Inputs!$F$19-Assumptions_and_Inputs!$B$25,Supporting_Schedules!I24<Assumptions_and_Inputs!$F$20-Assumptions_and_Inputs!$B$25)),1,0) | K10: =SUM(C10:J10)
A11: Core formula integrity | B11: Key statements are numeric; derived historical CFO ties to source. | C11: =IF(OR(ISERROR(Financial_Statements!B6),ISERROR(Financial_Statements!B29),ISERROR(Financial_Statements!B34)),1,0) | D11: =IF(OR(ISERROR(Financial_Statements!C6),ISERROR(Financial_Statements!C29),ISERROR(Financial_Statements!C34),ABS(Financial_Statements!C45-Historical_Data!C30)>Assumptions_and_Inputs!$B$25),1,0) | E11: =IF(OR(ISERROR(Financial_Statements!D6),ISERROR(Financial_Statements!D29),ISERROR(Financial_Statements!D34),ABS(Financial_Statements!D45-Historical_Data!D30)>Assumptions_and_Inputs!$B$25),1,0) | F11: =IF(OR(ISERROR(Financial_Statements!E6),ISERROR(Financial_Statements!E12),ISERROR(Financial_Statements!E20),ISERROR(Financial_Statements!E29),ISERROR(Financial_Statements!E34),ISERROR(Financial_Statements!E55)),1,0) | G11: =IF(OR(ISERROR(Financial_Statements!F6),ISERROR(Financial_Statements!F12),ISERROR(Financial_Statements!F20),ISERROR(Financial_Statements!F29),ISERROR(Financial_Statements!F34),ISERROR(Financial_Statements!F55)),1,0) | H11: =IF(OR(ISERROR(Financial_Statements!G6),ISERROR(Financial_Statements!G12),ISERROR(Financial_Statements!G20),ISERROR(Financial_Statements!G29),ISERROR(Financial_Statements!G34),ISERROR(Financial_Statements!G55)),1,0) | I11: =IF(OR(ISERROR(Financial_Statements!H6),ISERROR(Financial_Statements!H12),ISERROR(Financial_Statements!H20),ISERROR(Financial_Statements!H29),ISERROR(Financial_Statements!H34),ISERROR(Financial_Statements!H55)),1,0) | J11: =IF(OR(ISERROR(Financial_Statements!I6),ISERROR(Financial_Statements!I12),ISERROR(Financial_Statements!I20),ISERROR(Financial_Statements!I29),ISERROR(Financial_Statements!I34),ISERROR(Financial_Statements!I55)),1,0) | K11: =SUM(C11:J11)
A12: Scenario probabilities | B12: Scenario probability weights sum to 100%. | C12: =0 | D12: =0 | E12: =0 | F12: =0 | G12: =0 | H12: =0 | I12: =0 | J12: =0 | K12: =IF(ABS(SUM(Assumptions_and_Inputs!$B$22:$E$22)-1)<=0.000001,0,1)
A13: Scenario ranges | B13: Growth, operating cost, and working-capital assumptions are within valid ranges. | C13: =0 | D13: =0 | E13: =0 | F13: =0 | G13: =0 | H13: =0 | I13: =0 | J13: =0 | K13: =IF(OR(MIN(Assumptions_and_Inputs!$B$6:$E$6)<=-1,MIN(Assumptions_and_Inputs!$B$8:$E$8)<0,MAX(Assumptions_and_Inputs!$B$8:$E$8)>1,MIN(Assumptions_and_Inputs!$B$10:$E$12)<0),1,0)
A14: Sensitivity integrity | B14: Two-way sensitivity grid is numeric and its center reconciles to 2030 EBITDA. | C14: =0 | D14: =0 | E14: =0 | F14: =0 | G14: =0 | H14: =0 | I14: =0 | J14: =0 | K14: =IF(OR(COUNT(Sensitivity_Analysis!$C$7:$G$11)<>25,ABS(Sensitivity_Analysis!$F$13)>Assumptions_and_Inputs!$B$25),1,0)
A15: Scenario output integrity | B15: All four scenario revenue, EBITDA, cash, and debt outcomes are numeric. | C15: =0 | D15: =0 | E15: =0 | F15: =0 | G15: =0 | H15: =0 | I15: =0 | J15: =0 | K15: =IF(COUNT(Scenario_Analysis!$B$5:$E$9)<>20,1,0)
A16: Scenario balance-sheet integrity | B16: All scenario-specific balance sheets remain in accounting balance. | C16: =0 | D16: =0 | E16: =0 | F16: =0 | G16: =0 | H16: =0 | I16: =0 | J16: =0 | K16: =IF(OR(ABS(MIN(Scenario_Analysis!$B$41:$F$41))>Assumptions_and_Inputs!$B$25,ABS(MAX(Scenario_Analysis!$B$41:$F$41))>Assumptions_and_Inputs!$B$25,ABS(MIN(Scenario_Analysis!$B$71:$F$71))>Assumptions_and_Inputs!$B$25,ABS(MAX(Scenario_Analysis!$B$71:$F$71))>Assumptions_and_Inputs!$B$25,ABS(MIN(Scenario_Analysis!$B$101:$F$101))>Assumptions_and_Inputs!$B$25,ABS(MAX(Scenario_Analysis!$B$101:$F$101))>Assumptions_and_Inputs!$B$25,ABS(MIN(Scenario_Analysis!$B$131:$F$131))>Assumptions_and_Inputs!$B$25,ABS(MAX(Scenario_Analysis!$B$131:$F$131))>Assumptions_and_Inputs!$B$25),1,0)
A17: Selected-case reconciliation | B17: Selected scenario outputs tie to the integrated financial statements. | C17: =0 | D17: =0 | E17: =0 | F17: =0 | G17: =0 | H17: =0 | I17: =0 | J17: =0 | K17: =IF(OR(ABS(INDEX(Scenario_Analysis!$B$5:$E$5,1,MATCH(Assumptions_and_Inputs!$B$4,Assumptions_and_Inputs!$B$5:$E$5,0))-Financial_Statements!$I$6)>Assumptions_and_Inputs!$B$25,ABS(INDEX(Scenario_Analysis!$B$6:$E$6,1,MATCH(Assumptions_and_Inputs!$B$4,Assumptions_and_Inputs!$B$5:$E$5,0))-Financial_Statements!$I$12)>Assumptions_and_Inputs!$B$25,ABS(INDEX(Scenario_Analysis!$B$8:$E$8,1,MATCH(Assumptions_and_Inputs!$B$4,Assumptions_and_Inputs!$B$5:$E$5,0))-Financial_Statements!$I$25)>Assumptions_and_Inputs!$B$25,ABS(INDEX(Scenario_Analysis!$B$9:$E$9,1,MATCH(Assumptions_and_Inputs!$B$4,Assumptions_and_Inputs!$B$5:$E$5,0))-Financial_Statements!$I$31)>Assumptions_and_Inputs!$B$25),1,0)

Sheet Historical_Data
A1: Historical_Data | Reported source data and explicit source mappings
A2: =IF(Model_Checks!$B$2=0,"ALL CHECKS PASSED","MODEL CHECKS FAILED")
A3: Amok Equipment AS | NOK unless stated | Generated 2026-10-10 | Version 1.0
A4: Source annual accounts (NOK) | B4: 2023 | C4: 2024 | D4: 2025
A5: Revenue | B5: 18015123 | C5: 20366506 | D5: 16231415
A6: Reported total operating expenses | B6: 15617768 | C6: 19614314 | D6: 17310195
A7: Personnel expenses | B7: 4280871 | C7: 5120437 | D7: 4393760
A8: Reported operating profit (EBIT) | B8: 2397355 | C8: 752192 | D8: -1078780
A9: Net financial income / (expense) | B9: 1363480 | C9: 58522 | D9: 204270
A10: Reported income tax expense / (benefit) | B10: 574566 | C10: 185081 | D10: -174711
A11: Reported net income | B11: 3186270 | C11: 625633 | D11: -699798
A12: Net fixed assets | B12: 87189 | C12: 227959 | D12: 469295
A13: Total current assets | B13: 25410571 | C13: 22865984 | D13: 20371955
A14: Inventory (reported; 2025 not separately disclosed) | B14: 10110389 | C14: 12314240
A15: Accounts receivable | B15: 6278761 | C15: 2032768 | D15: 1909557
A16: Cash and cash equivalents | B16: 9021420 | C16: 8518975 | D16: 6914012
A17: Reported total assets | B17: 25497760 | C17: 23093943 | D17: 20841249
A18: Short-term liabilities | B18: 4930776 | C18: 3910158 | D18: 2357263
A19: Long-term liabilities | B19: 3433 | C19: 0
A20: Reported total liabilities | B20: 4934209 | C20: 3910158 | D20: 2357263
A21: Reported shareholders' equity | B21: 20563551 | C21: 19183784 | D21: 18483986
A23: Cash flow source data (NOK; reported cash-flow reconciliation inputs)
B24: 2023 | C24: 2024 | D24: 2025
A25: Net income (cash flow source) | C25: 625633 | D25: -699798
A26: Depreciation and amortization | B26: 0 | C26: 0 | D26: 0
A27: Accounts receivable cash-flow impact | C27: 4245993 | D27: 123211
A28: Inventory cash-flow impact | C28: -2203851 | D28: 765854
A29: Accounts payable cash-flow impact | C29: -1020618 | D29: -1552895
A30: Reported estimated cash from operations | C30: 1647157 | D30: -1363628
A31: Opening cash | C31: 9021420 | D31: 8518975
A32: Closing cash | C32: 8518975 | D32: 6914012
A33: Unallocated other cash flows (source) | C33: -2149602 | D33: -241335
A35: Source notes
A36: 2025 inventory was not separately reported; the model treats current assets excluding cash and receivables as inventory / other operating current assets.
A37: 2024 reported balance sheet totals differ by NOK 1 due to source rounding. Historical cash flows include unallocated cash movements because investing/financing detail was not supplied.
A38: Annual statements are historical reported figures. Financial_Statements derives non-personnel operating expenses as reported total operating expenses less reported personnel expenses.
